<robot name="example_track" xmlns:xacro="http://www.ros.org/wiki/xacro">

    <!-- URDF file for general ROS systems such as ros_control, rviz, etc.           -->
    <!-- We define here;                                                             -->
    <!--     * a base_link to be wrapped by the track                                     -->
    <!--     * a sprocket to drive the track                                         -->
    <!--     * an axle and actuator for the sprocket                                 -->
    <!--     * an idler wheel on the other side of the sprocket                      -->
    <!-- Other entities specialized for Gazebo are defined in *_gazebo.urdf.xacro .  -->

    <xacro:macro name="make_box_inertia" params="mass size_x size_y size_z">
        <inertial>
            <mass value="${mass}" />
            <inertia ixx="${mass * (size_y * size_y + size_z * size_z) / 12}" ixy="0" ixz="0" iyy="${mass * (size_z * size_z + size_x * size_x) / 12}" iyz="0" izz="${mass * (size_x * size_x + size_y * size_y) / 12}" />
        </inertial>
    </xacro:macro>

    <xacro:macro name="make_wheel_inertia" params="mass radius length">
        <inertial>
            <mass value="${mass}" />
            <!-- assuming axis of cylinder is y, not z -->
            <inertia ixx="${mass * (radius * radius / 4 + length * length / 12)}" ixy="0" ixz="0" iyy="${mass * radius * radius / 2}" iyz="0" izz="${mass * (radius * radius / 4 + length * length / 12)}" />
        </inertial>
    </xacro:macro>

    <!-- base_link to be wrapped by the track -->

    <link name="base_link">
        <xacro:make_box_inertia mass="50" size_x="0.5" size_y="0.325" size_z="0.1" />

        <visual>
            <geometry>
                <box size="0.1 0.1 0.1" />
            </geometry>
        </visual>

        <collision>
            <geometry>
                <box size="0.1 0.1 0.1" />
            </geometry>
        </collision>
    </link>

    <!-- sprocket driving the track -->
    <link name="sprocket_left">
        <xacro:make_wheel_inertia mass="2.0" radius="0.064" length="0.1115" />

        <visual>
            <origin xyz="0 0 0" rpy="${pi / 2} 0 0" />
            <geometry>
                <cylinder radius="0.064" length="0.1115" />
            </geometry>
        </visual>
        <visual>
            <geometry>
                <box size="0.01 0.1115 0.1" />
            </geometry>
        </visual>
        <visual>
            <geometry>
                <box size="0.1 0.1115 0.01" />
            </geometry>
        </visual>

        <collision>
            <origin xyz="0 0 0" rpy="${pi / 2} 0 0" />
            <geometry>
                <cylinder radius="0.064" length="0.1115" />
            </geometry>
        </collision>
    </link>
    <joint name="sprocket_left_axle" type="continuous">
        <origin xyz="0.2 0.095 0" rpy="0 0 0" />
        <parent link="base_link" />
        <child link="sprocket_left" />
        <axis xyz="0 1 0" />
    </joint>
    <transmission name="sprocket_left_transmission">
        <type>transmission_interface/SimpleTransmission</type>
        <joint name="sprocket_left_axle">
            <hardwareInterface>hardware_interface/VelocityJointInterface</hardwareInterface>
        </joint>
        <actuator name="sprocket_left_actuator">
            <hardwareInterface>hardware_interface/VelocityJointInterface</hardwareInterface>
            <mechanicalReduction>1</mechanicalReduction>
        </actuator>
    </transmission>

    <!-- idler on the other side of the sprocket -->
    <link name="idler_left">
        <xacro:make_wheel_inertia mass="2.0" radius="0.064" length="0.1115" />

        <visual>
            <origin xyz="0 0 0" rpy="${pi / 2} 0 0" />
            <geometry>
                <cylinder radius="0.064" length="0.1115" />
            </geometry>
        </visual>

        <collision>
            <origin xyz="0 0 0" rpy="${pi / 2} 0 0" />
            <geometry>
                <cylinder radius="0.064" length="0.1115" />
            </geometry>
        </collision>
    </link>
    <joint name="idler_left_axle" type="fixed">
        <origin xyz="-0.2 0.095 0" rpy="0 0 0" />
        <parent link="base_link" />
        <child link="idler_left" />
    </joint>

    <!-- sprocket driving the track -->
    <link name="sprocket_right">
        <xacro:make_wheel_inertia mass="2.0" radius="0.064" length="0.1115" />
        <visual>
            <origin xyz="0 0 0" rpy="${pi / 2} 0 0" />
            <geometry>
                <cylinder radius="0.064" length="0.1115" />
            </geometry>
        </visual>
        <visual>
            <geometry>
                <box size="0.01 0.1115 0.1" />
            </geometry>
        </visual>
        <visual>
            <geometry>
                <box size="0.1 0.1115 0.01" />
            </geometry>
        </visual>
        <collision>
            <origin xyz="0 0 0" rpy="${pi / 2} 0 0" />
            <geometry>
                <cylinder radius="0.064" length="0.1115" />
            </geometry>
        </collision>
    </link>
    <joint name="sprocket_right_axle" type="continuous">
        <origin xyz="0.2 -0.095 0" rpy="0 0 0" />
        <parent link="base_link" />
        <child link="sprocket_right" />
        <axis xyz="0 1 0" />
    </joint>
    <transmission name="sprocket_right_transmission">
        <type>transmission_interface/SimpleTransmission</type>
        <joint name="sprocket_right_axle">
            <hardwareInterface>hardware_interface/VelocityJointInterface</hardwareInterface>
        </joint>
        <actuator name="sprocket_right_actuator">
            <hardwareInterface>hardware_interface/VelocityJointInterface</hardwareInterface>
            <mechanicalReduction>1</mechanicalReduction>
        </actuator>
    </transmission>

    <!-- idler on the other side of the sprocket -->
    <link name="idler_right">
        <xacro:make_wheel_inertia mass="2.0" radius="0.064" length="0.1115" />
        <visual>
            <origin xyz="0 0 0" rpy="${pi / 2} 0 0" />
            <geometry>
                <cylinder radius="0.064" length="0.1115" />
            </geometry>
        </visual>
        <collision>
            <origin xyz="0 0 0" rpy="${pi / 2} 0 0" />
            <geometry>
                <cylinder radius="0.064" length="0.1115" />
            </geometry>
        </collision>
    </link>
    <joint name="idler_right_axle" type="fixed">
        <origin xyz="-0.2 -0.095 0" rpy="0 0 0" />
        <parent link="base_link" />
        <child link="idler_right" />
    </joint>

    <!-- flipper fl -->
    <link name="flipper_fl_link">
    </link>
    <joint name="flipper_fl_joint" type="continuous">
        <origin xyz="0.2 0.295 0" rpy="0 0 0" />
        <parent link="base_link" />
        <child link="flipper_fl_link" />
        <axis xyz="0.0 1.0 0.0"/>
    </joint>
    <transmission name="flipper_fl_transmission">
        <type>transmission_interface/SimpleTransmission</type>
        <joint name="flipper_fl_joint">
            <hardwareInterface>hardware_interface/EffortJointInterface</hardwareInterface>
        </joint>
        <actuator name="flipper_fl_actuator">
            <mechanicalReduction>1</mechanicalReduction>
        </actuator>
    </transmission>
    <link name="flipper_fl_sprocket">
        <xacro:make_wheel_inertia mass="2.0" radius="0.064" length="0.1115" />
        <visual>
            <origin xyz="0 0 0" rpy="${pi / 2} 0 0" />
            <geometry>
                <cylinder radius="0.064" length="0.1115" />
            </geometry>
        </visual>

        <!-- <collision>
            <origin xyz="0 0 0" rpy="${pi / 2} 0 0" />
            <geometry>
                <cylinder radius="0.064" length="0.1115" />
            </geometry>
        </collision> -->
    </link>
    <joint name="flipper_fl_sprocket_axle" type="continuous">
        <origin xyz="0.0 0.0 0" rpy="0 0 0" />
        <parent link="flipper_fl_link" />
        <child link="flipper_fl_sprocket" />
        <axis xyz="0.0 1.0 0.0"/>
    </joint>
    <transmission name="flipper_fl_sprocket_axle_transmission">
        <type>transmission_interface/SimpleTransmission</type>
        <joint name="flipper_fl_sprocket_axle">
            <hardwareInterface>hardware_interface/VelocityJointInterface</hardwareInterface>
        </joint>
        <actuator name="flipper_fl_sprocket_axle_actuator">
            <hardwareInterface>hardware_interface/VelocityJointInterface</hardwareInterface>
            <mechanicalReduction>1</mechanicalReduction>
        </actuator>
    </transmission>
    <link name="flipper_fl_idler">
        <xacro:make_wheel_inertia mass="2.0" radius="0.0225" length="0.1115" />
        <visual>
            <origin xyz="0 0 0" rpy="${pi / 2} 0 0" />
            <geometry>
                <cylinder radius="0.0225" length="0.1115" />
            </geometry>
        </visual>
        <!-- <collision>
            <origin xyz="0 0 0" rpy="${pi / 2} 0 0" />
            <geometry>
                <cylinder radius="0.0225" length="0.1115" />
            </geometry>
        </collision> -->
    </link>
    <joint name="flipper_fl_idler_axle" type="fixed">
        <origin xyz="0.26 0.0 0" rpy="0 0 0" />
        <parent link="flipper_fl_link" />
        <child link="flipper_fl_idler" />
    </joint>

    <!-- flipper fr -->
    <link name="flipper_fr_link">
    </link>
    <joint name="flipper_fr_joint" type="continuous">
        <origin xyz="0.2 -0.295 0" rpy="0 0 0" />
        <parent link="base_link" />
        <child link="flipper_fr_link" />
        <axis xyz="0.0 1.0 0.0"/>
    </joint>
    <transmission name="flipper_fr_transmission">
        <type>transmission_interface/SimpleTransmission</type>
        <joint name="flipper_fr_joint">
            <hardwareInterface>hardware_interface/EffortJointInterface</hardwareInterface>
        </joint>
        <actuator name="flipper_fr_actuator">
            <mechanicalReduction>1</mechanicalReduction>
        </actuator>
    </transmission>
    <link name="flipper_fr_sprocket">
        <xacro:make_wheel_inertia mass="2.0" radius="0.064" length="0.1115" />
        <visual>
            <origin xyz="0 0 0" rpy="${pi / 2} 0 0" />
            <geometry>
                <cylinder radius="0.064" length="0.1115" />
            </geometry>
        </visual>

        <!-- <collision>
            <origin xyz="0 0 0" rpy="${pi / 2} 0 0" />
            <geometry>
                <cylinder radius="0.064" length="0.1115" />
            </geometry>
        </collision> -->
    </link>
    <joint name="flipper_fr_sprocket_axle" type="continuous">
        <origin xyz="0.0 0.0 0" rpy="0 0 0" />
        <parent link="flipper_fr_link" />
        <child link="flipper_fr_sprocket" />
        <axis xyz="0.0 1.0 0.0"/>
    </joint>
    <transmission name="flipper_fr_sprocket_axle_transmission">
        <type>transmission_interface/SimpleTransmission</type>
        <joint name="flipper_fr_sprocket_axle">
            <hardwareInterface>hardware_interface/VelocityJointInterface</hardwareInterface>
        </joint>
        <actuator name="flipper_fr_sprocket_axle_actuator">
            <hardwareInterface>hardware_interface/VelocityJointInterface</hardwareInterface>
            <mechanicalReduction>1</mechanicalReduction>
        </actuator>
    </transmission>
    <link name="flipper_fr_idler">
        <xacro:make_wheel_inertia mass="2.0" radius="0.0225" length="0.1115" />
        <visual>
            <origin xyz="0 0 0" rpy="${pi / 2} 0 0" />
            <geometry>
                <cylinder radius="0.0225" length="0.1115" />
            </geometry>
        </visual>
        <!-- <collision>
            <origin xyz="0 0 0" rpy="${pi / 2} 0 0" />
            <geometry>
                <cylinder radius="0.0225" length="0.1115" />
            </geometry>
        </collision> -->
    </link>
    <joint name="flipper_fr_idler_axle" type="fixed">
        <origin xyz="0.26 0.0 0" rpy="0 0 0" />
        <parent link="flipper_fr_link" />
        <child link="flipper_fr_idler" />
    </joint>

</robot>